<mujoco model="cheetah">
  <compiler angle="radian" autolimits="true"/>
  <option timestep="0.01"/>
  <size nstack="300000" nuser_geom="1"/>
  <include file="../misc/visual.xml"/>
  <include file="../misc/materials.xml"/>
  <include file="../misc/skybox.xml"/>

  <default class="main">
    <joint limited="true" solimplimit="0 0.8 0.03 0.5 2" stiffness="8" armature="0.1" damping="0.01"/>
    <geom conaffinity="0" friction="0.4 0.1 0.1" solimp="0 0.8 0.01 0.5 2" material="self"/>
    <general ctrllimited="true" ctrlrange="-1 1"/>
  </default>
  
  <worldbody>
    <geom name="floor" size="40 40 40" type="plane" conaffinity="1" material="grid"/>
    <light pos="0 0 1.3" dir="-0.5547 0 -0.83205" directional="true" cutoff="100" exponent="1" diffuse="1 1 1" specular="0.1 0.1 0.1"/>
    <body name="torso" pos="0 0 0.7" gravcomp="0">
      <joint name="rootx" pos="0 0 0" axis="1 0 0" limited="false" type="slide" stiffness="0" armature="0" damping="0"/>
      <joint name="rootz" pos="0 0 0" axis="0 0 1" limited="false" type="slide" stiffness="0" armature="0" damping="0"/>
      <joint name="rooty" pos="0 0 0" axis="0 1 0" limited="false" stiffness="0" armature="0" damping="0"/>
      <geom name="torso" size="0.046 0.5" quat="0.707107 0 -0.707107 0" type="capsule"/>
      <geom name="head" size="0.046 0.15" pos="0.6 0 0.1" quat="0.90687 0 0.42141 0" type="capsule"/>
      <camera name="tilted" pos="2.9 3.2 0.3" quat="0.660169 -0.660169 0.253331 -0.253331" mode="trackcom"/>
      <camera name="track" pos="0 3 0.3" quat="0.707107 -0.707107 0 0" mode="trackcom"/>
      <body name="bthigh" pos="-0.5 0 0" gravcomp="0">
        <joint name="bthigh" pos="0 0 0" axis="0 1 0" stiffness="240" range="-0.52 1.05" damping="6"/>
        <geom name="bthigh" size="0.046 0.145" pos="0.1 0 -0.13" quat="-0.32329 0 -0.9463 0" type="capsule"/>
      </body>
      <body name="fthigh" pos="0.5 0 0" gravcomp="0">
        <joint name="fthigh" pos="0 0 0" axis="0 1 0" stiffness="180" range="-1 0.7" damping="4.5"/>
        <geom name="fthigh" size="0.046 0.133" pos="-0.07 0 -0.12" quat="0.96639 0 0.257081 0" type="capsule"/>
      </body>
    </body>
  </worldbody>
  <actuator>
    <general name="bthigh" joint="bthigh" gear="120 0 0 0 0 0" actdim="0"/>
    <general name="fthigh" joint="fthigh" gear="120 0 0 0 0 0" actdim="0"/>
  </actuator>
</mujoco>
