<mujoco model="cheetah">
  <compiler angle="radian" autolimits="true"/>
  <option timestep="0.01"/>
  <size nstack="300000" nuser_geom="1"/>
  <visual>
    <quality shadowsize="2048"/>
    <headlight ambient="0.4 0.4 0.4" diffuse="0.8 0.8 0.8" specular="0.1 0.1 0.1"/>
  </visual>
  <default class="main">
    <joint limited="true" solimplimit="0 0.8 0.03 0.5 2" stiffness="8" armature="0.1" damping="0.01"/>
    <geom conaffinity="0" friction="0.4 0.1 0.1" solimp="0 0.8 0.01 0.5 2" material="self"/>
    <general ctrllimited="true" ctrlrange="-1 1"/>
  </default>
  <asset>
    <texture type="skybox" name="skybox" builtin="gradient" mark="random" rgb1="0.4 0.6 0.8" rgb2="0 0 0" markrgb="1 1 1" width="800" height="4800"/>
    <texture type="2d" name="grid" builtin="checker" mark="edge" rgb1="0.1 0.2 0.3" rgb2="0.2 0.3 0.4" markrgb="0.2 0.3 0.4" width="300" height="300"/>
    <material name="grid" texture="grid" texuniform="true" reflectance="0.2"/>
    <material name="self" rgba="0.7 0.5 0.3 1"/>
    <material name="self_default" rgba="0.7 0.5 0.3 1"/>
    <material name="self_highlight" rgba="0 0.5 0.3 1"/>
    <material name="effector" rgba="0.7 0.4 0.2 1"/>
    <material name="effector_default" rgba="0.7 0.4 0.2 1"/>
    <material name="effector_highlight" rgba="0 0.5 0.3 1"/>
    <material name="decoration" rgba="0.3 0.5 0.7 1"/>
    <material name="eye" rgba="0 0.2 1 1"/>
    <material name="target" rgba="0.6 0.3 0.3 1"/>
    <material name="target_default" rgba="0.6 0.3 0.3 1"/>
    <material name="target_highlight" rgba="0.6 0.3 0.3 0.4"/>
    <material name="site" rgba="0.5 0.5 0.5 0.3"/>
  </asset>
  <worldbody>
    <geom name="floor" size="40 40 40" type="plane" conaffinity="1" material="grid"/>
    <light pos="0 0 1.3" dir="-0.5547 0 -0.83205" directional="true" cutoff="100" exponent="1" diffuse="1 1 1" specular="0.1 0.1 0.1"/>
    <body name="torso" pos="0 0 0.7" gravcomp="0">
      <joint name="rootx" pos="0 0 0" axis="1 0 0" limited="false" type="slide" stiffness="0" armature="0" damping="0"/>
      <joint name="rootz" pos="0 0 0" axis="0 0 1" limited="false" type="slide" stiffness="0" armature="0" damping="0"/>
      <joint name="rooty" pos="0 0 0" axis="0 1 0" limited="false" stiffness="0" armature="0" damping="0"/>
      <geom name="torso" size="0.046 0.5" quat="0.707107 0 -0.707107 0" type="capsule"/>
      <geom name="head" size="0.046 0.15" pos="0.6 0 0.1" quat="0.90687 0 0.42141 0" type="capsule"/>
      <camera name="tilted" pos="2.9 3.2 0.3" quat="0.660169 -0.660169 0.253331 -0.253331" mode="trackcom"/>
      <camera name="track" pos="0 3 0.3" quat="0.707107 -0.707107 0 0" mode="trackcom"/>
      <body name="fthigh" pos="0.5 0 0" gravcomp="0">
        <joint name="fthigh" pos="0 0 0" axis="0 1 0" stiffness="180" range="-1 0.7" damping="4.5"/>
        <geom name="fthigh" size="0.046 0.133" pos="-0.07 0 -0.12" quat="0.96639 0 0.257081 0" type="capsule"/>
      </body>
    </body>
  </worldbody>
  <actuator>
    <general name="fthigh" joint="fthigh" gear="120 0 0 0 0 0" actdim="0"/>
  </actuator>
</mujoco>
