<mujoco model="humanoid">
  <compiler angle="radian" autolimits="true"/>
  <option integrator="RK4"/>
  <include file="../misc/visual.xml"/>
  <include file="../misc/materials.xml"/>
  <include file="../misc/skybox.xml"/>

  <default class="main">
    <joint limited="true" armature="1" damping="1"/>
    <geom conaffinity="0" friction="0.7 0.1 0.1" material="self"/>
    <general ctrllimited="true" ctrlrange="-1 1"/>
  </default>

  <worldbody>
    <geom name="floor" size="20 20 0.125" type="plane" conaffinity="1" material="grid"/>
    <light pos="0 0 1.3" dir="-0.5547 0 -0.83205" directional="true" cutoff="100" exponent="1" diffuse="1 1 1" specular="0.1 0.1 0.1"/>
    <body name="torso" pos="0 0 1.4" gravcomp="0">
      <joint name="abdomen_x" pos="0 0 0" axis="1 0 0" limited="false" type="slide" armature="0.02" damping="0"/>
      <joint name="abdomen_z" pos="0 0 0" axis="0 0 1" limited="false" type="slide" ref="1.25" armature="0.02" damping="0"/>
      <joint name="abdomen_y" pos="0 0 1.1" axis="0 1 0" limited="false" armature="0.02" damping="0"/>
      <geom name="torso1" size="0.07 0.07" quat="0.707107 0.707107 0 0" type="capsule"/>
      <geom name="head" size="0.09" pos="0 0 0.19"/>
      <geom name="uwaist" size="0.06 0.06" pos="-0.01 0 -0.12" quat="0.707107 0.707107 0 0" type="capsule"/>
      <geom name="lwaist" size="0.06 0.06" pos="-0.01 0 -0.26" quat="0.707107 0.707107 0 0" type="capsule"/>
      <geom name="butt" size="0.09 0.07" pos="-0.02 0 -0.425" quat="0.707107 0.707107 0 0" type="capsule"/>
      <camera name="tilted" pos="3.6 4 -0.2" quat="0.660169 -0.660169 0.253331 -0.253331" mode="trackcom"/>
      <camera name="track" pos="0 4 0" quat="0.707107 -0.707107 0 0" mode="trackcom"/>
      <body name="left_thigh" pos="0 0.1 -0.465" gravcomp="0">
        <joint name="left_hip_y" pos="0 0 0" axis="0 1 0" stiffness="20" range="-1.91986 0.349066" armature="0.01" damping="5"/>
        <geom name="left_thigh1" size="0.06 0.170074" pos="0 -0.005 -0.17" quat="0.999892 -0.0147011 0 0" type="capsule"/>
        <body name="left_shin" pos="0 -0.01 -0.403" gravcomp="0">
          <joint name="left_knee" pos="0 0 0.02" axis="0 -1 0" stiffness="1" range="-2.79253 -0.0349066" armature="0.006"/>
          <geom name="left_shin1" size="0.049 0.15" pos="0 0 -0.15" type="capsule"/>
          <geom name="left_foot" size="0.075" pos="0 0 -0.35"/>
        </body>
      </body>
      <body name="right_upper_arm" pos="0 -0.17 0.06" gravcomp="0">
        <joint name="right_shoulder1" pos="0 0 0" axis="0 -1 0" stiffness="1" range="-1.48353 1.0472" armature="0.006"/>
        <geom name="right_uarm1" size="0.04 0.138564" pos="0.08 -0.08 -0.08" quat="0.888074 -0.325058 -0.325058 0" type="capsule"/>
        <body name="right_lower_arm" pos="0.18 -0.18 -0.18" gravcomp="0">
          <joint name="right_elbow" pos="0 0 0" axis="0 -1 0" range="-1.5708 0.872665" armature="0.0028"/>
          <geom name="right_larm" size="0.031 0.138564" pos="0.09 0.09 0.09" quat="0.459701 0.627963 -0.627963 0" type="capsule"/>
          <geom name="right_hand" size="0.04" pos="0.18 0.18 0.18"/>
          <camera pos="0 0 0"/>
        </body>
      </body>
      <body name="left_upper_arm" pos="0 0.17 0.06" gravcomp="0">
        <joint name="left_shoulder1" pos="0 0 0" axis="0 -1 0" stiffness="1" range="-1.0472 1.48353" armature="0.006"/>
        <geom name="left_uarm1" size="0.04 0.138564" pos="0.08 0.08 -0.08" quat="0.888074 0.325058 -0.325058 0" type="capsule"/>
        <body name="left_lower_arm" pos="0.18 0.18 -0.18" gravcomp="0">
          <joint name="left_elbow" pos="0 0 0" axis="0 -1 0" range="-1.5708 0.872665" armature="0.0028"/>
          <geom name="left_larm" size="0.031 0.138564" pos="0.09 -0.09 0.09" quat="0.459701 -0.627963 -0.627963 0" type="capsule"/>
          <geom name="left_hand" size="0.04" pos="0.18 -0.18 0.18"/>
        </body>
      </body>
    </body>
  </worldbody>
  <actuator>
    <general name="left_hip_y" joint="left_hip_y" gear="150 0 0 0 0 0" actdim="0"/>
    <general name="left_knee" joint="left_knee" gear="100 0 0 0 0 0" actdim="0"/>
    <general name="right_shoulder1" joint="right_shoulder1" gear="12.5 0 0 0 0 0" actdim="0"/>
    <general name="right_elbow" joint="right_elbow" gear="12.5 0 0 0 0 0" actdim="0"/>
    <general name="left_shoulder1" joint="left_shoulder1" gear="12.5 0 0 0 0 0" actdim="0"/>
    <general name="left_elbow" joint="left_elbow" gear="12.5 0 0 0 0 0" actdim="0"/>
  </actuator>
</mujoco>
